Workbook
Name Slicer_Department: #N/A
Name Slicer_Gender: #N/A
Name Slicer_Payment_Method: #N/A
Name Slicer_Readmission: #N/A
Name Slicer_Treatment_Type: #N/A

Sheet questions
A1: 1. What is the average length of stay for patients across all departments? | B1: =AVERAGE('source Data'!$J$1:$J$16) -> 5.6
A2: 2. Which department has the highest number of patients? | B2: {=INDEX('source Data'!$G$2:$G$16,_xlfn.MODE.SNGL(MATCH('source Data'!$G$2:$G$16,'source Data'!$G$2:$G$16,0)))} -> Cardiology
A3: 3. What is the total revenue generated by the hospital? | B3: =SUM('source Data'!$K$2:$K$16) -> 76850 | C3: KPI
A4: 4. What is the average patient satisfaction score? | B4: =AVERAGE('source Data'!$O$2:$O$16) -> 7.8666667 | C4: KPI
A5: 5. What percentage of patients were admitted in emergency conditions? | B5: =COUNTIFS('source Data'!$Q$2:$Q$16,"Yes")/COUNTA('source Data'!$A$2:$A$16) -> 0.26666667
A6: 6. What is the mortality rate among patients? | B6: =COUNTIFS('source Data'!$R$2:$R$16,"Deceased")/COUNTA('source Data'!$A$2:$A$16) -> 0.13333333
A7: 7. What is the average patient satisfaction score? | B7: =AVERAGE('source Data'!$O$2:$O$16) -> 7.8666667
A8: 8. Which payment method is most common? | B8: {=INDEX('source Data'!$L$2:$L$16,_xlfn.MODE.SNGL(MATCH('source Data'!$L$2:$L$16,'source Data'!$L$2:$L$16,0)))} -> Insurance
A9: 9. What is the average bill amount for patients with insurance vs. those without insurance? | B9: =AVERAGEIFS('source Data'!$K$2:$K$16,'source Data'!$N$2:$N$16,'source Data'!N3) -> 9012.5 | C9: =AVERAGEIFS('source Data'!$K$2:$K$16,'source Data'!$N$2:$N$16,'source Data'!N2) -> 678.57143
A10: 10. Which age group has the highest number of patients?
A11: 11. What is the department-wise average patient satisfaction score?

Sheet ANALYSIS
A1: Average length of stay by department
I2: ="Top Department: " & INDEX(ANALYSIS!I4:I10,MATCH(MAX(ANALYSIS!J4:J10),ANALYSIS!J4:J10,0)) & "(" & MAX(ANALYSIS!J4:J10) & "patients)" -> Top Department: Cardiology(4patients)
A3: Row Labels | B3: Average of Length of Stay | D3: Row Labels | E3: Sum of Total Bill Amount | G3: Row Labels | H3: Count of Readmission | I3: Row Labels | J3: Count of Patient ID | L3: Row Labels | M3: Average of Total Bill Amount
A4: Cardiology | B4: 6 | D4: Gynecology | E4: 300 | G4: Angina | H4: 1 | I4: Cardiology | J4: 4 | L4: Insured | M4: 9012.5
A5: Geriatrics | B5: 7 | D5: Pediatrics | E5: 1100 | G5: Arrhythmia | H5: 1 | I5: Geriatrics | J5: 1 | L5: Not Insured | M5: 678.57143
A6: Gynecology | B6: 2 | D6: Geriatrics | E6: 3000 | G6: Asthma | H6: 1 | I6: Gynecology | J6: 1 | L6: Grand Total | M6: 5123.3333
A7: Neurology | B7: 4.5 | D7: Orthopedics | E7: 6350 | G7: Cancer | H7: 1 | I7: Neurology | J7: 4
A8: Oncology | B8: 15 | D8: Neurology | E8: 14000 | G8: Dislocation | H8: 1 | I8: Oncology | J8: 1
A9: Orthopedics | B9: 4 | D9: Oncology | E9: 25000 | G9: Epilepsy | H9: 1 | I9: Orthopedics | J9: 3
A10: Pediatrics | B10: 6 | D10: Cardiology | E10: 27100 | G10: Fracture | H10: 2 | I10: Pediatrics | J10: 1 | L10: Row Labels | M10: Count of Patient ID
A11: Grand Total | B11: 5.6 | D11: Grand Total | E11: 76850 | G11: Heart Attack | H11: 1 | I11: Grand Total | J11: 15 | L11: Deceased | M11: 2
G12: Hypertension | H12: 1 | L12: Survived | M12: 13
G13: Migraine | H13: 2 | L13: Grand Total | M13: 15
G14: Pneumonia | H14: 1
G15: Pregnancy | H15: 1 | I15: Row Labels | J15: Average of Satisfaction Score
A16: Row Labels | B16: Count of Patient ID | G16: Stroke | H16: 1 | I16: Cardiology | J16: 6.75 | L16: Row Labels | M16: Count of Patient ID
A17: No | B17: 11 | D17: ="Largest Age Group: " & INDEX(ANALYSIS!D19:D25, MATCH(MAX(ANALYSIS!E19:E25),ANALYSIS!E19:E25,0)) -> Largest Age Group: 28-37 | G17: Grand Total | H17: 15 | I17: Geriatrics | J17: 5 | L17: Cardiology | M17: 4
A18: Yes | B18: 4 | D18: Row Labels | E18: Count of Patient ID | I18: Gynecology | J18: 10 | L18: Geriatrics | M18: 1
A19: Grand Total | B19: 15 | D19: 18-27 | E19: 2 | I19: Neurology | J19: 8.75 | L19: Gynecology | M19: 1
D20: 28-37 | E20: 4 | I20: Oncology | J20: 6 | L20: Neurology | M20: 4
D21: 38-47 | E21: 2 | I21: Orthopedics | J21: 8.3333333 | L21: Oncology | M21: 1
A22: ="Most Common Payment Method: "& INDEX(A24:A26, MATCH(MAX(B24:B26),B24:B26,0)) -> Most Common Payment Method: Insurance | D22: 48-57 | E22: 3 | I22: Pediatrics | J22: 10 | L22: Orthopedics | M22: 3
A23: Row Labels | B23: Count of Patient ID | D23: 58-67 | E23: 2 | I23: Grand Total | J23: 7.8666667 | L23: Pediatrics | M23: 1
A24: Cash | B24: 4 | D24: 68-77 | E24: 1 | L24: Grand Total | M24: 15
A25: Credit Card | B25: 3 | D25: 78-87 | E25: 1
A26: Insurance | B26: 8 | D26: Grand Total | E26: 15
A27: Grand Total | B27: 15
B30: KPIs
B31: Sum of Total Bill Amount | D31: Count of Patient ID | G31: Average of Satisfaction Score | K31: Row Labels | L31: Count of Patient ID | O31: Average of Length of Stay
B32: 76850 | D32: 15 | G32: 7.8666667 | K32: Deceased | L32: 2 | O32: 5.6
B33: =GETPIVOTDATA("Total Bill Amount",$B$31) -> 76850 | D33: =GETPIVOTDATA("Patient ID",$D$31) -> 15 | G33: =GETPIVOTDATA("Satisfaction Score",$G$31) -> 7.8666667 | K33: Survived | L33: 13 | O33: =GETPIVOTDATA("Length of Stay",$O$31) -> 5.6
K34: Grand Total | L34: 15
D38: Count of Patient ID | E38: Column Labels | J38: Row Labels | K38: Sum of Total Bill Amount
D39: Row Labels | E39: No | F39: Yes | G39: Grand Total | J39: Cash | K39: 3100
D40: Angina | E40: 1 | G40: 1 | J40: Credit Card | K40: 1650
D41: Arrhythmia | E41: 1 | G41: 1 | J41: Insurance | K41: 72100
D42: Asthma | E42: 1 | G42: 1 | J42: Grand Total | K42: 76850
D43: Cancer | F43: 1 | G43: 1
D44: Dislocation | E44: 1 | G44: 1
D45: Epilepsy | E45: 1 | G45: 1 | J45: Row Labels | K45: Count of Patient ID | M45: Row Labels | N45: Count of Patient ID
...

Sheet HOSPITAL OVERVIEW

Sheet Hospital Dashboard

Sheet source Data
A1: Patient ID | B1: Age | C1: Age Group | D1: Gender | E1: Admission Date | F1: Discharge Date | G1: Department | H1: Diagnosis | I1: Treatment Type | J1: Length of Stay | K1: Total Bill Amount | L1: Payment Method | M1: Insurance Provider | N1: Insurance Status | O1: Satisfaction Score | P1: Readmission | Q1: Emergency Admission | R1: Mortality Status
A2: P0001 | B2: 25 | C2: {=_xlfn.IFS('source Data'!$B2<=25,"18-25",'source Data'!$B2<=35,"26-35",'source Data'!$B2<=45,"36-45",'source Data'!$B2<=55,"46-55",'source Data'!$B2<=65,"56-65",'source Data'!$B2<=80,"66-80")} -> 18-25 | D2: Female | E2: 45301 | F2: 45303 | G2: Orthopedics | H2: Fracture | I2: Therapy | J2: 2 | K2: 450 | L2: Credit Card | M2: None | N2: =IF('source Data'!$M2="None","Not Insured","Insured") -> Not Insured | O2: 8 | P2: No | Q2: No | R2: Survived
A3: P0002 | B3: 60 | C3: {=_xlfn.IFS('source Data'!$B3<=25,"18-25",'source Data'!$B3<=35,"26-35",'source Data'!$B3<=45,"36-45",'source Data'!$B3<=55,"46-55",'source Data'!$B3<=65,"56-65",'source Data'!$B3<=80,"66-80")} -> 56-65 | D3: Male | E3: 45327 | F3: 45337 | G3: Cardiology | H3: Hypertension | I3: Medication | J3: 10 | K3: 2100 | L3: Insurance | M3: Aetna | N3: =IF('source Data'!$M3="None","Not Insured","Insured") -> Insured | O3: 7 | P3: Yes | Q3: No | R3: Survived
A4: P0003 | B4: 34 | C4: {=_xlfn.IFS('source Data'!$B4<=25,"18-25",'source Data'!$B4<=35,"26-35",'source Data'!$B4<=45,"36-45",'source Data'!$B4<=55,"46-55",'source Data'!$B4<=65,"56-65",'source Data'!$B4<=80,"66-80")} -> 26-35 | D4: Female | E4: 45371 | F4: 45375 | G4: Neurology | H4: Migraine | I4: Observation | J4: 4 | K4: 700 | L4: Cash | M4: None | N4: =IF('source Data'!$M4="None","Not Insured","Insured") -> Not Insured | O4: 9 | P4: No | Q4: Yes | R4: Survived
A5: P0004 | B5: 45 | C5: {=_xlfn.IFS('source Data'!$B5<=25,"18-25",'source Data'!$B5<=35,"26-35",'source Data'!$B5<=45,"36-45",'source Data'!$B5<=55,"46-55",'source Data'!$B5<=65,"56-65",'source Data'!$B5<=80,"66-80")} -> 36-45 | D5: Male | E5: 45383 | F5: 45387 | G5: Cardiology | H5: Arrhythmia | I5: Surgery | J5: 4 | K5: 8000 | L5: Insurance | M5: Blue Cross | N5: =IF('source Data'!$M5="None","Not Insured","Insured") -> Insured | O5: 6 | P5: No | Q5: No | R5: Survived
A6: P0005 | B6: 18 | C6: {=_xlfn.IFS('source Data'!$B6<=25,"18-25",'source Data'!$B6<=35,"26-35",'source Data'!$B6<=45,"36-45",'source Data'!$B6<=55,"46-55",'source Data'!$B6<=65,"56-65",'source Data'!$B6<=80,"66-80")} -> 18-25 | D6: Female | E6: 45426 | F6: 45432 | G6: Pediatrics | H6: Asthma | I6: Medication | J6: 6 | K6: 1100 | L6: Cash | M6: None | N6: =IF('source Data'!$M6="None","Not Insured","Insured") -> Not Insured | O6: 10 | P6: No | Q6: Yes | R6: Survived
A7: P0006 | B7: 72 | C7: {=_xlfn.IFS('source Data'!$B7<=25,"18-25",'source Data'!$B7<=35,"26-35",'source Data'!$B7<=45,"36-45",'source Data'!$B7<=55,"46-55",'source Data'!$B7<=65,"56-65",'source Data'!$B7<=80,"66-80")} -> 66-80 | D7: Male | E7: 45453 | F7: 45458 | G7: Neurology | H7: Stroke | I7: Surgery | J7: 5 | K7: 12000 | L7: Insurance | M7: Aetna | N7: =IF('source Data'!$M7="None","Not Insured","Insured") -> Insured | O7: 8 | P7: Yes | Q7: No | R7: Deceased
A8: P0007 | B8: 29 | C8: {=_xlfn.IFS('source Data'!$B8<=25,"18-25",'source Data'!$B8<=35,"26-35",'source Data'!$B8<=45,"36-45",'source Data'!$B8<=55,"46-55",'source Data'!$B8<=65,"56-65",'source Data'!$B8<=80,"66-80")} -> 26-35 | D8: Male | E8: 45495 | F8: 45500 | G8: Orthopedics | H8: Dislocation | I8: Therapy | J8: 5 | K8: 900 | L8: Credit Card | M8: None | N8: =IF('source Data'!$M8="None","Not Insured","Insured") -> Not Insured | O8: 9 | P8: No | Q8: No | R8: Survived
A9: P0008 | B9: 52 | C9: {=_xlfn.IFS('source Data'!$B9<=25,"18-25",'source Data'!$B9<=35,"26-35",'source Data'!$B9<=45,"36-45",'source Data'!$B9<=55,"46-55",'source Data'!$B9<=65,"56-65",'source Data'!$B9<=80,"66-80")} -> 46-55 | D9: Female | E9: 45519 | F9: 45524 | G9: Cardiology | H9: Heart Attack | I9: Surgery | J9: 5 | K9: 15000 | L9: Insurance | M9: Cigna | N9: =IF('source Data'!$M9="None","Not Insured","Insured") -> Insured | O9: 7 | P9: No | Q9: Yes | R9: Survived
A10: P0009 | B10: 40 | C10: {=_xlfn.IFS('source Data'!$B10<=25,"18-25",'source Data'!$B10<=35,"26-35",'source Data'!$B10<=45,"36-45",'source Data'!$B10<=55,"46-55",'source Data'!$B10<=65,"56-65",'source Data'!$B10<=80,"66-80")} -> 36-45 | D10: Male | E10: 45540 | F10: 45545 | G10: Neurology | H10: Epilepsy | I10: Medication | J10: 5 | K10: 500 | L10: Cash | M10: None | N10: =IF('source Data'!$M10="None","Not Insured","Insured") -> Not Insured | O10: 9 | P10: No | Q10: No | R10: Survived
A11: P0010 | B11: 37 | C11: {=_xlfn.IFS('source Data'!$B11<=25,"18-25",'source Data'!$B11<=35,"26-35",'source Data'!$B11<=45,"36-45",'source Data'!$B11<=55,"46-55",'source Data'!$B11<=65,"56-65",'source Data'!$B11<=80,"66-80")} -> 36-45 | D11: Female | E11: 45566 | F11: 45568 | G11: Gynecology | H11: Pregnancy | I11: Observation | J11: 2 | K11: 300 | L11: Credit Card | M11: None | N11: =IF('source Data'!$M11="None","Not Insured","Insured") -> Not Insured | O11: 10 | P11: No | Q11: No | R11: Survived
A12: P0011 | B12: 65 | C12: {=_xlfn.IFS('source Data'!$B12<=25,"18-25",'source Data'!$B12<=35,"26-35",'source Data'!$B12<=45,"36-45",'source Data'!$B12<=55,"46-55",'source Data'!$B12<=65,"56-65",'source Data'!$B12<=80,"66-80")} -> 56-65 | D12: Male | E12: 45580 | F12: 45595 | G12: Oncology | H12: Cancer | I12: Chemotherapy | J12: 15 | K12: 25000 | L12: Insurance | M12: Aetna | N12: =IF('source Data'!$M12="None","Not Insured","Insured") -> Insured | O12: 6 | P12: Yes | Q12: No | R12: Survived
A13: P0012 | B13: 80 | C13: {=_xlfn.IFS('source Data'!$B13<=25,"18-25",'source Data'!$B13<=35,"26-35",'source Data'!$B13<=45,"36-45",'source Data'!$B13<=55,"46-55",'source Data'!$B13<=65,"56-65",'source Data'!$B13<=80,"66-80")} -> 66-80 | D13: Female | E13: 45601 | F13: 45608 | G13: Geriatrics | H13: Pneumonia | I13: Medication | J13: 7 | K13: 3000 | L13: Insurance | M13: Blue Cross | N13: =IF('source Data'!$M13="None","Not Insured","Insured") -> Insured | O13: 5 | P13: Yes | Q13: Yes | R13: Deceased
... A16: P0015 | B16: 55 | C16: {=_xlfn.IFS('source Data'!$B16<=25,"18-25",'source Data'!$B16<=35,"26-35",'source Data'!$B16<=45,"36-45",'source Data'!$B16<=55,"46-55",'source Data'!$B16<=65,"56-65",'source Data'!$B16<=80,"66-80")} -> 46-55 | D16: Male | E16: 45636 | F16: 45641 | G16: Orthopedics | H16: Fracture | I16: Surgery | J16: 5 | K16: 5000 | L16: Insurance | M16: Blue Cross | N16: =IF('source Data'!$M16="None","Not Insured","Insured") -> Insured | O16: 8 | P16: No | Q16: No | R16: Survived

Sheet DASHBOARD
